<?xml version="1.0" ?>
<robot name="pr2_left_arm">
  <joint name="l_shoulder_pan_joint" type="revolute">
    <axis xyz="0 0 1"/>
    <origin rpy="0 0 0" xyz="0.0 0.188 0.0"/> <!-- transform from parent link to this joint frame -->
    <parent link="world"/>
    <child link="l_shoulder_pan_link"/>
    <dynamics damping="10.0"/>
    <limit effort="10000" lower="-10000" upper="10000" velocity="10000"/>
  </joint>
  <link name="l_shoulder_pan_link">
    <inertial>
      <mass value="25.799322"/>
      <origin rpy="0 0 0" xyz="-0.001201 0.024513 -0.098231"/>
      <inertia ixx="0.866179142480" ixy="-0.06086507933" ixz="-0.12118061183" iyy="0.87421714893" iyz="-0.05886609911" izz="0.27353821674"/>
    </inertial>
  </link>
  <joint name="l_shoulder_lift_joint" type="revolute">
    <axis xyz="0 1 0"/>
    <origin rpy="0 0 0" xyz="0.1 0 0"/>
    <parent link="l_shoulder_pan_link"/>
    <child link="l_shoulder_lift_link"/>
    <limit effort="10000" lower="-10000" upper="10000" velocity="10000"/>
  </joint>
  <link name="l_shoulder_lift_link">
    <inertial>
      <mass value="2.74988"/>
      <origin rpy="0 0 0" xyz="0.02195 -0.02664 -0.03127"/>
      <inertia ixx="0.02105584615" ixy="0.00496704022" ixz="-0.00194808955" iyy="0.02127223737" iyz="0.00110425490" izz="0.01975753814"/>
    </inertial>
  </link>
  <joint name="l_upper_arm_roll_joint" type="revolute">
    <axis xyz="1 0 0"/>
    <origin rpy="0 0 0" xyz="0 0 0"/>
    <parent link="l_shoulder_lift_link"/>
    <child link="l_upper_arm_roll_link"/>
    <limit effort="10000" lower="-10000" upper="10000" velocity="10000"/>
  </joint>
  <link name="l_upper_arm_roll_link">
    <inertial>
      <!-- dummy mass, to be removed -->
      <mass value="0.1"/>
      <origin rpy="0 0 0" xyz="0.0 0 0"/>
      <inertia ixx="0.01" ixy="0.00" ixz="0.00" iyy="0.01" iyz="0.00" izz="0.01"/>
    </inertial>
  </link>
  <joint name="l_upper_arm_joint" type="fixed">
    <origin rpy="0 0 0" xyz="0 0 0"/>
    <parent link="l_upper_arm_roll_link"/>
    <child link="l_upper_arm_link"/>
  </joint>
  <link name="l_upper_arm_link">
    <inertial>
      <!-- NOTE:reflect==-1 for right side, reflect==1 for the left side -->
      <mass value="6.01769"/>
      <origin xyz="0.21405 0.01658 -0.00057"/>
      <inertia ixx="0.01530603856" ixy="-0.00339324862" ixz="0.00060765455" iyy="0.07473694455" iyz="-0.00019953729" izz="0.07601594191"/>
    </inertial>
  </link>
  <joint name="l_elbow_flex_joint" type="revolute">
    <axis xyz="0 1 0"/>
    <origin rpy="0 0 0" xyz="0.4 0 0"/>
    <parent link="l_upper_arm_link"/>
    <child link="l_elbow_flex_link"/>
    <limit effort="10000" lower="-10000" upper="10000" velocity="10000"/>
  </joint>
  <link name="l_elbow_flex_link">
    <inertial>
      <mass value="1.90327"/>
      <origin xyz="0.01014 0.00032 -0.01211"/>
      <inertia ixx="0.00346541989" ixy="0.00004066825" ixz="0.00043171614" iyy="0.00441606455" iyz="-0.00003968914" izz="0.00359156824"/>
    </inertial>
  </link>
  <joint name="l_forearm_roll_joint" type="continuous">
    <axis xyz="-1 0 0"/>
    <origin rpy="0 0 0" xyz="0 0 0"/>
    <parent link="l_elbow_flex_link"/>
    <child link="l_forearm_roll_link"/>
  </joint>
  <link name="l_forearm_roll_link">
    <inertial>
      <!-- dummy masses, to be removed -->
      <mass value="0.1"/>
      <origin xyz="0 0 0"/>
      <inertia ixx="0.01" ixy="0.00" ixz="0.00" iyy="0.01" iyz="0.00" izz="0.01"/>
    </inertial>
  </link>
  <joint name="l_forearm_joint" type="fixed">
    <origin rpy="0 0 0" xyz="0 0 0"/>
    <parent link="l_forearm_roll_link"/>
    <child link="l_forearm_link"/>
  </joint>
  <link name="l_forearm_link">
    <inertial>
      <mass value="2.57968"/>
      <origin xyz="0.18791 -0.00017 -0.00912"/>
      <inertia ixx="0.00364857222" ixy="0.00005215877" ixz="0.00071534842" iyy="0.01507736897" iyz="-0.00001310770" izz="0.01659310749"/>
    </inertial>
  </link>
  <joint name="l_wrist_flex_joint" type="revolute">
    <axis xyz="0 -1 0"/>
    <origin rpy="0 0 0" xyz="0.32025 0 0"/>
    <parent link="l_forearm_link"/>
    <child link="l_wrist_flex_link"/>
    <limit effort="10000" lower="-10000" upper="10000" velocity="10000"/>
  </joint>
  <link name="l_wrist_flex_link">
    <inertial>
      <mass value="0.61402"/>
      <origin xyz="-0.00157 0.0 -0.00075"/>
      <inertia ixx="0.00065165722" ixy="0.00000028864" ixz="0.00000303477" iyy="0.00019824443" iyz="-0.00000022645" izz="0.00064450498"/>
    </inertial>
  </link>
  <joint name="l_wrist_roll_joint" type="continuous">
    <axis xyz="1 0 0"/>
    <origin rpy="0 0 0" xyz="0 0 0"/>
    <parent link="l_wrist_flex_link"/>
    <child link="l_wrist_roll_link"/>
  </joint>
  <link name="l_wrist_roll_link">
    <inertial>
      <!-- dummy masses, to be removed.  wrist roll masses are on "gripper_palm" -->
      <mass value="0.1"/>
      <origin xyz="0 0 0"/>
      <inertia ixx="0.01" ixy="0" ixz="0" iyy="0.01" iyz="0" izz="0.01"/>
    </inertial>
  </link>
  <joint name="l_gripper_palm_joint" type="fixed">
    <origin rpy="0 0 0" xyz="0 0 0"/>
    <parent link="l_wrist_roll_link"/>
    <child link="l_gripper_palm_link"/>
  </joint>
  <link name="l_gripper_palm_link">
    <inertial>
      <mass value="0.58007"/>
      <origin rpy="0 0 0" xyz="0.06623 0.00053 -0.00119"/>
      <inertia ixx="0.00035223921" ixy="-0.00001580476" ixz="-0.00000091750" iyy="0.00067741312" iyz="-0.00000059554" izz="0.00086563316"/>
    </inertial>
  </link>
  <joint name="l_gripper_motor_accelerometer_joint" type="fixed">
    <origin rpy="0 0 0" xyz="0 0 0"/>
    <parent link="l_gripper_palm_link"/>
    <child link="l_gripper_motor_accelerometer_link"/>
  </joint>
  <link name="l_gripper_motor_accelerometer_link">
    <inertial>
      <mass value="0.001"/>
      <origin rpy="0 0 0" xyz="0 0 0"/>
      <inertia ixx="0.001" ixy="0.0" ixz="0.0" iyy="0.001" iyz="0.0" izz="0.001"/>
    </inertial>
  </link>
  <joint name="l_gripper_l_finger_joint" type="revolute">
    <axis xyz="0 0 1"/>
    <origin rpy="0 0 0" xyz="0.07691 0.01 0"/>
    <parent link="l_gripper_palm_link"/>
    <child link="l_gripper_l_finger_link"/>
    <limit effort="10000" lower="-10000" upper="10000" velocity="10000"/>
  </joint>
  <link name="l_gripper_l_finger_link">
    <inertial>
      <mass value="0.17126"/>
      <origin rpy="0 0 0" xyz="0.03598 0.01730 -0.00164"/>
      <inertia ixx="0.00007756198" ixy="0.00000149095" ixz="-0.00000983385" iyy="0.00019708305" iyz="-0.00000306125" izz="0.00018105446"/>
    </inertial>
  </link>
  <joint name="l_gripper_r_finger_joint" type="revolute">
    <axis xyz="0 0 -1"/>
    <origin rpy="0 0 0" xyz="0.07691 -0.01 0"/>
    <parent link="l_gripper_palm_link"/>
    <child link="l_gripper_r_finger_link"/>
    <limit effort="10000" lower="-10000" upper="10000" velocity="10000"/>
  </joint>
  <link name="l_gripper_r_finger_link">
    <inertial>
      <mass value="0.17389"/>
      <origin rpy="0 0 0" xyz="0.03576 -0.01736 -0.00095"/>
      <inertia ixx="0.00007738410" ixy="-0.00000209309" ixz="-0.00000836228" iyy="0.00019847383" iyz="0.00000246110" izz="0.00018106988"/>
    </inertial>
  </link>
  <joint name="l_gripper_l_finger_tip_joint" type="revolute">
    <axis xyz="0 0 -1"/>
    <origin rpy="0 0 0" xyz="0.09137 0.00495 0"/>
    <parent link="l_gripper_l_finger_link"/>
    <child link="l_gripper_l_finger_tip_link"/>
    <limit effort="10000" lower="-10000" upper="10000" velocity="10000"/>
  </joint>
  <link name="l_gripper_l_finger_tip_link">
    <inertial>
      <mass value="0.04419"/>
      <origin rpy="0 0 0" xyz="0.00423 0.00284 0.0"/>
      <inertia ixx="0.00000837047" ixy="0.00000583632" ixz="0.0" iyy="0.00000987067" iyz="0.0" izz="0.00001541768"/>
    </inertial>
  </link>
  <joint name="l_gripper_r_finger_tip_joint" type="revolute">
    <axis xyz="0 0 1"/>
    <origin rpy="0 0 0" xyz="0.09137 -0.00495 0"/>
    <parent link="l_gripper_r_finger_link"/>
    <child link="l_gripper_r_finger_tip_link"/>
    <limit effort="10000" lower="-10000" upper="10000" velocity="10000"/>
  </joint>
  <link name="l_gripper_r_finger_tip_link">
    <inertial>
      <mass value="0.04419"/>
      <origin rpy="0 0 0" xyz="0.00423 -0.00284 0.0"/>
      <inertia ixx="0.00000837047" ixy="-0.00000583632" ixz="0.0" iyy="0.00000987067" iyz="0.0" izz="0.00001541768"/>
    </inertial>
  </link>
</robot>
